package com.gao.test3;

import java.io.File;
import java.io.FileInputStream;
import java.io.FileNotFoundException;
import java.io.FileOutputStream;
import java.io.IOException;

public class Test14 {
	public static void test() throws MyException{//1.如果遇到 throws , 那么异常会抛给 本方法的调用处 去解决
		if(2>1){
			throw new MyException();
		}
	}
	@SuppressWarnings("resource")
	public static void main(String[] args) throws MyException {
		
		
		try {	//2.如果 try catch 会尝试着捕获异常  捕获成功程序继续向下执行  捕获失败 抛给方法调用者
			test();
		} catch (ArrayIndexOutOfBoundsException e) {
			e.printStackTrace();
		}
		

		File file = new File("D:\\Test\\test.txt");
		FileInputStream fis = null;
		FileOutputStream fos = null;
		
		try {
		    fis = new FileInputStream(file);
		    fos = new FileOutputStream("f:\\result.txt");
			int read = fis.read();
			
			while(read != -1){
				fos.write(read);
				System.out.println((char)read);
				read = fis.read();
			}
			
		}catch (FileNotFoundException e) {
			// TODO Auto-generated catch block
			e.printStackTrace();
		} catch (IOException e) {
			// TODO Auto-generated catch block
			e.printStackTrace();
		}finally {
			try {
				fis.close();
				fos.close();
			} catch (IOException e) {
				// TODO Auto-generated catch block
				e.printStackTrace();
			}
		}
		
		
		
	}
}
